1 change detected
1 change detected
1 change detected
1 change detected
1 change detected
1 change detected
2 changes detected
1 change detected
1 change detected
1 change detected
1 change detected
1 change detected
2 changes detected
1 change detected
1 change detected
3 changes detected
1 change detected
1 change detected
1 change detected
2 changes detected
1 change detected
2 changes detected
1 change detected
1 change detected
1 change detected
1 change detected
2 changes detected
1 change detected
2 changes detected
1 change detected
1 change detected
2 changes detected
1 change detected
1 change detected
1 change detected
2 changes detected
unhandled exception during asyncio.run() shutdown
task: <Task finished name='Task-29' coro=<<async_generator_asend without __name__>()> exception=RuntimeError('cannot schedule new futures after shutdown')>
Traceback (most recent call last):
  File "/Users/minkijung/anaconda3/envs/survey_buddy/lib/python3.12/site-packages/aiostream/stream/combine.py", line 159, in func
    yield await corofn(arg, *args)
          ^^^^^^^^^^^^^^^^^^^^^^^^
  File "/Users/minkijung/anaconda3/envs/survey_buddy/lib/python3.12/site-packages/modal/mount.py", line 466, in _put_file
    response = await retry_transient_errors(resolver.client.stub.MountPutFile, request2, base_delay=1)
               ^^^^^^^^^^^^^^^^^^^^^^^^^^^^^^^^^^^^^^^^^^^^^^^^^^^^^^^^^^^^^^^^^^^^^^^^^^^^^^^^^^^^^^^
  File "/Users/minkijung/anaconda3/envs/survey_buddy/lib/python3.12/site-packages/modal/_utils/grpc_utils.py", line 249, in retry_transient_errors
    return await fn(*args, metadata=metadata, timeout=timeout)
           ^^^^^^^^^^^^^^^^^^^^^^^^^^^^^^^^^^^^^^^^^^^^^^^^^^^
  File "/Users/minkijung/anaconda3/envs/survey_buddy/lib/python3.12/site-packages/grpclib/client.py", line 903, in __call__
    await stream.send_message(message, end=True)
  File "/Users/minkijung/anaconda3/envs/survey_buddy/lib/python3.12/site-packages/grpclib/client.py", line 241, in send_message
    await self.send_request()
  File "/Users/minkijung/anaconda3/envs/survey_buddy/lib/python3.12/site-packages/grpclib/client.py", line 173, in send_request
    protocol = await self._channel.__connect__()
               ^^^^^^^^^^^^^^^^^^^^^^^^^^^^^^^^^
  File "/Users/minkijung/anaconda3/envs/survey_buddy/lib/python3.12/site-packages/modal/_utils/grpc_utils.py", line 114, in __connect__
    protocol = await self._create_connection()
               ^^^^^^^^^^^^^^^^^^^^^^^^^^^^^^^
  File "/Users/minkijung/anaconda3/envs/survey_buddy/lib/python3.12/site-packages/grpclib/client.py", line 725, in _create_connection
    _, protocol = await self._loop.create_connection(
                  ^^^^^^^^^^^^^^^^^^^^^^^^^^^^^^^^^^^
  File "/Users/minkijung/anaconda3/envs/survey_buddy/lib/python3.12/asyncio/base_events.py", line 1078, in create_connection
    infos = await self._ensure_resolved(
            ^^^^^^^^^^^^^^^^^^^^^^^^^^^^
  File "/Users/minkijung/anaconda3/envs/survey_buddy/lib/python3.12/asyncio/base_events.py", line 1454, in _ensure_resolved
    return await loop.getaddrinfo(host, port, family=family, type=type,
           ^^^^^^^^^^^^^^^^^^^^^^^^^^^^^^^^^^^^^^^^^^^^^^^^^^^^^^^^^^^^
  File "/Users/minkijung/anaconda3/envs/survey_buddy/lib/python3.12/asyncio/base_events.py", line 899, in getaddrinfo
    return await self.run_in_executor(
                 ^^^^^^^^^^^^^^^^^^^^^
  File "/Users/minkijung/anaconda3/envs/survey_buddy/lib/python3.12/asyncio/base_events.py", line 861, in run_in_executor
    executor.submit(func, *args), loop=self)
    ^^^^^^^^^^^^^^^^^^^^^^^^^^^^
  File "/Users/minkijung/anaconda3/envs/survey_buddy/lib/python3.12/concurrent/futures/thread.py", line 170, in submit
    raise RuntimeError('cannot schedule new futures after shutdown')
RuntimeError: cannot schedule new futures after shutdown
unhandled exception during asyncio.run() shutdown
task: <Task finished name='Task-31' coro=<<async_generator_asend without __name__>()> exception=RuntimeError('cannot schedule new futures after shutdown')>
Traceback (most recent call last):
  File "/Users/minkijung/anaconda3/envs/survey_buddy/lib/python3.12/site-packages/aiostream/manager.py", line 82, in cancel_task
    await task
  File "/Users/minkijung/anaconda3/envs/survey_buddy/lib/python3.12/site-packages/aiostream/stream/combine.py", line 159, in func
    yield await corofn(arg, *args)
          ^^^^^^^^^^^^^^^^^^^^^^^^
  File "/Users/minkijung/anaconda3/envs/survey_buddy/lib/python3.12/site-packages/modal/mount.py", line 466, in _put_file
    response = await retry_transient_errors(resolver.client.stub.MountPutFile, request2, base_delay=1)
               ^^^^^^^^^^^^^^^^^^^^^^^^^^^^^^^^^^^^^^^^^^^^^^^^^^^^^^^^^^^^^^^^^^^^^^^^^^^^^^^^^^^^^^^
  File "/Users/minkijung/anaconda3/envs/survey_buddy/lib/python3.12/site-packages/modal/_utils/grpc_utils.py", line 249, in retry_transient_errors
    return await fn(*args, metadata=metadata, timeout=timeout)
           ^^^^^^^^^^^^^^^^^^^^^^^^^^^^^^^^^^^^^^^^^^^^^^^^^^^
  File "/Users/minkijung/anaconda3/envs/survey_buddy/lib/python3.12/site-packages/grpclib/client.py", line 903, in __call__
    await stream.send_message(message, end=True)
  File "/Users/minkijung/anaconda3/envs/survey_buddy/lib/python3.12/site-packages/grpclib/client.py", line 241, in send_message
    await self.send_request()
  File "/Users/minkijung/anaconda3/envs/survey_buddy/lib/python3.12/site-packages/grpclib/client.py", line 173, in send_request
    protocol = await self._channel.__connect__()
               ^^^^^^^^^^^^^^^^^^^^^^^^^^^^^^^^^
  File "/Users/minkijung/anaconda3/envs/survey_buddy/lib/python3.12/site-packages/modal/_utils/grpc_utils.py", line 114, in __connect__
    protocol = await self._create_connection()
               ^^^^^^^^^^^^^^^^^^^^^^^^^^^^^^^
  File "/Users/minkijung/anaconda3/envs/survey_buddy/lib/python3.12/site-packages/grpclib/client.py", line 725, in _create_connection
    _, protocol = await self._loop.create_connection(
                  ^^^^^^^^^^^^^^^^^^^^^^^^^^^^^^^^^^^
  File "/Users/minkijung/anaconda3/envs/survey_buddy/lib/python3.12/asyncio/base_events.py", line 1078, in create_connection
    infos = await self._ensure_resolved(
            ^^^^^^^^^^^^^^^^^^^^^^^^^^^^
  File "/Users/minkijung/anaconda3/envs/survey_buddy/lib/python3.12/asyncio/base_events.py", line 1454, in _ensure_resolved
    return await loop.getaddrinfo(host, port, family=family, type=type,
           ^^^^^^^^^^^^^^^^^^^^^^^^^^^^^^^^^^^^^^^^^^^^^^^^^^^^^^^^^^^^
  File "/Users/minkijung/anaconda3/envs/survey_buddy/lib/python3.12/asyncio/base_events.py", line 899, in getaddrinfo
    return await self.run_in_executor(
                 ^^^^^^^^^^^^^^^^^^^^^
  File "/Users/minkijung/anaconda3/envs/survey_buddy/lib/python3.12/asyncio/base_events.py", line 861, in run_in_executor
    executor.submit(func, *args), loop=self)
    ^^^^^^^^^^^^^^^^^^^^^^^^^^^^
  File "/Users/minkijung/anaconda3/envs/survey_buddy/lib/python3.12/concurrent/futures/thread.py", line 170, in submit
    raise RuntimeError('cannot schedule new futures after shutdown')
RuntimeError: cannot schedule new futures after shutdown
1 change detected
1 change detected
unhandled exception during asyncio.run() shutdown
task: <Task finished name='Task-16' coro=<Resolver.load.<locals>.loader() done, defined at /Users/minkijung/anaconda3/envs/survey_buddy/lib/python3.12/site-packages/modal/_resolver.py:118> exception=RuntimeError('cannot schedule new futures after shutdown')>
Traceback (most recent call last):
  File "/Users/minkijung/anaconda3/envs/survey_buddy/lib/python3.12/site-packages/modal/_resolver.py", line 149, in load
    return await cached_future
           ^^^^^^^^^^^^^^^^^^^
  File "/Users/minkijung/anaconda3/envs/survey_buddy/lib/python3.12/site-packages/modal/_resolver.py", line 125, in loader
    await obj._load(obj, self, existing_object_id)
  File "/Users/minkijung/anaconda3/envs/survey_buddy/lib/python3.12/site-packages/modal/image.py", line 400, in _load
    await join()
  File "/Users/minkijung/anaconda3/envs/survey_buddy/lib/python3.12/site-packages/modal/image.py", line 383, in join
    async for response in unary_stream(resolver.client.stub.ImageJoinStreaming, request):
  File "/Users/minkijung/anaconda3/envs/survey_buddy/lib/python3.12/site-packages/modal/_utils/grpc_utils.py", line 202, in unary_stream
    await stream.send_message(request, end=True)
  File "/Users/minkijung/anaconda3/envs/survey_buddy/lib/python3.12/site-packages/grpclib/client.py", line 241, in send_message
    await self.send_request()
  File "/Users/minkijung/anaconda3/envs/survey_buddy/lib/python3.12/site-packages/grpclib/client.py", line 173, in send_request
    protocol = await self._channel.__connect__()
               ^^^^^^^^^^^^^^^^^^^^^^^^^^^^^^^^^
  File "/Users/minkijung/anaconda3/envs/survey_buddy/lib/python3.12/site-packages/modal/_utils/grpc_utils.py", line 114, in __connect__
    protocol = await self._create_connection()
               ^^^^^^^^^^^^^^^^^^^^^^^^^^^^^^^
  File "/Users/minkijung/anaconda3/envs/survey_buddy/lib/python3.12/site-packages/grpclib/client.py", line 725, in _create_connection
    _, protocol = await self._loop.create_connection(
                  ^^^^^^^^^^^^^^^^^^^^^^^^^^^^^^^^^^^
  File "/Users/minkijung/anaconda3/envs/survey_buddy/lib/python3.12/asyncio/base_events.py", line 1078, in create_connection
    infos = await self._ensure_resolved(
            ^^^^^^^^^^^^^^^^^^^^^^^^^^^^
  File "/Users/minkijung/anaconda3/envs/survey_buddy/lib/python3.12/asyncio/base_events.py", line 1454, in _ensure_resolved
    return await loop.getaddrinfo(host, port, family=family, type=type,
           ^^^^^^^^^^^^^^^^^^^^^^^^^^^^^^^^^^^^^^^^^^^^^^^^^^^^^^^^^^^^
  File "/Users/minkijung/anaconda3/envs/survey_buddy/lib/python3.12/asyncio/base_events.py", line 899, in getaddrinfo
    return await self.run_in_executor(
                 ^^^^^^^^^^^^^^^^^^^^^
  File "/Users/minkijung/anaconda3/envs/survey_buddy/lib/python3.12/asyncio/base_events.py", line 861, in run_in_executor
    executor.submit(func, *args), loop=self)
    ^^^^^^^^^^^^^^^^^^^^^^^^^^^^
  File "/Users/minkijung/anaconda3/envs/survey_buddy/lib/python3.12/concurrent/futures/thread.py", line 170, in submit
    raise RuntimeError('cannot schedule new futures after shutdown')
RuntimeError: cannot schedule new futures after shutdown
unhandled exception during asyncio.run() shutdown
task: <Task finished name='Task-29' coro=<<async_generator_asend without __name__>()> exception=RuntimeError('cannot schedule new futures after shutdown')>
Traceback (most recent call last):
  File "/Users/minkijung/anaconda3/envs/survey_buddy/lib/python3.12/site-packages/aiostream/manager.py", line 82, in cancel_task
    await task
  File "/Users/minkijung/anaconda3/envs/survey_buddy/lib/python3.12/site-packages/aiostream/stream/combine.py", line 159, in func
    yield await corofn(arg, *args)
          ^^^^^^^^^^^^^^^^^^^^^^^^
  File "/Users/minkijung/anaconda3/envs/survey_buddy/lib/python3.12/site-packages/modal/mount.py", line 443, in _put_file
    response = await retry_transient_errors(resolver.client.stub.MountPutFile, request, base_delay=1)
               ^^^^^^^^^^^^^^^^^^^^^^^^^^^^^^^^^^^^^^^^^^^^^^^^^^^^^^^^^^^^^^^^^^^^^^^^^^^^^^^^^^^^^^
  File "/Users/minkijung/anaconda3/envs/survey_buddy/lib/python3.12/site-packages/modal/_utils/grpc_utils.py", line 249, in retry_transient_errors
    return await fn(*args, metadata=metadata, timeout=timeout)
           ^^^^^^^^^^^^^^^^^^^^^^^^^^^^^^^^^^^^^^^^^^^^^^^^^^^
  File "/Users/minkijung/anaconda3/envs/survey_buddy/lib/python3.12/site-packages/grpclib/client.py", line 903, in __call__
    await stream.send_message(message, end=True)
  File "/Users/minkijung/anaconda3/envs/survey_buddy/lib/python3.12/site-packages/grpclib/client.py", line 241, in send_message
    await self.send_request()
  File "/Users/minkijung/anaconda3/envs/survey_buddy/lib/python3.12/site-packages/grpclib/client.py", line 173, in send_request
    protocol = await self._channel.__connect__()
               ^^^^^^^^^^^^^^^^^^^^^^^^^^^^^^^^^
  File "/Users/minkijung/anaconda3/envs/survey_buddy/lib/python3.12/site-packages/modal/_utils/grpc_utils.py", line 114, in __connect__
    protocol = await self._create_connection()
               ^^^^^^^^^^^^^^^^^^^^^^^^^^^^^^^
  File "/Users/minkijung/anaconda3/envs/survey_buddy/lib/python3.12/site-packages/grpclib/client.py", line 725, in _create_connection
    _, protocol = await self._loop.create_connection(
                  ^^^^^^^^^^^^^^^^^^^^^^^^^^^^^^^^^^^
  File "/Users/minkijung/anaconda3/envs/survey_buddy/lib/python3.12/asyncio/base_events.py", line 1078, in create_connection
    infos = await self._ensure_resolved(
            ^^^^^^^^^^^^^^^^^^^^^^^^^^^^
  File "/Users/minkijung/anaconda3/envs/survey_buddy/lib/python3.12/asyncio/base_events.py", line 1454, in _ensure_resolved
    return await loop.getaddrinfo(host, port, family=family, type=type,
           ^^^^^^^^^^^^^^^^^^^^^^^^^^^^^^^^^^^^^^^^^^^^^^^^^^^^^^^^^^^^
  File "/Users/minkijung/anaconda3/envs/survey_buddy/lib/python3.12/asyncio/base_events.py", line 899, in getaddrinfo
    return await self.run_in_executor(
                 ^^^^^^^^^^^^^^^^^^^^^
  File "/Users/minkijung/anaconda3/envs/survey_buddy/lib/python3.12/asyncio/base_events.py", line 861, in run_in_executor
    executor.submit(func, *args), loop=self)
    ^^^^^^^^^^^^^^^^^^^^^^^^^^^^
  File "/Users/minkijung/anaconda3/envs/survey_buddy/lib/python3.12/concurrent/futures/thread.py", line 170, in submit
    raise RuntimeError('cannot schedule new futures after shutdown')
RuntimeError: cannot schedule new futures after shutdown
unhandled exception during asyncio.run() shutdown
task: <Task finished name='Task-23' coro=<<async_generator_asend without __name__>()> exception=RuntimeError('cannot schedule new futures after shutdown')>
Traceback (most recent call last):
  File "/Users/minkijung/anaconda3/envs/survey_buddy/lib/python3.12/site-packages/aiostream/manager.py", line 82, in cancel_task
    await task
  File "/Users/minkijung/anaconda3/envs/survey_buddy/lib/python3.12/site-packages/aiostream/stream/combine.py", line 159, in func
    yield await corofn(arg, *args)
          ^^^^^^^^^^^^^^^^^^^^^^^^
  File "/Users/minkijung/anaconda3/envs/survey_buddy/lib/python3.12/site-packages/modal/mount.py", line 466, in _put_file
    response = await retry_transient_errors(resolver.client.stub.MountPutFile, request2, base_delay=1)
               ^^^^^^^^^^^^^^^^^^^^^^^^^^^^^^^^^^^^^^^^^^^^^^^^^^^^^^^^^^^^^^^^^^^^^^^^^^^^^^^^^^^^^^^
  File "/Users/minkijung/anaconda3/envs/survey_buddy/lib/python3.12/site-packages/modal/_utils/grpc_utils.py", line 249, in retry_transient_errors
    return await fn(*args, metadata=metadata, timeout=timeout)
           ^^^^^^^^^^^^^^^^^^^^^^^^^^^^^^^^^^^^^^^^^^^^^^^^^^^
  File "/Users/minkijung/anaconda3/envs/survey_buddy/lib/python3.12/site-packages/grpclib/client.py", line 903, in __call__
    await stream.send_message(message, end=True)
  File "/Users/minkijung/anaconda3/envs/survey_buddy/lib/python3.12/site-packages/grpclib/client.py", line 241, in send_message
    await self.send_request()
  File "/Users/minkijung/anaconda3/envs/survey_buddy/lib/python3.12/site-packages/grpclib/client.py", line 173, in send_request
    protocol = await self._channel.__connect__()
               ^^^^^^^^^^^^^^^^^^^^^^^^^^^^^^^^^
  File "/Users/minkijung/anaconda3/envs/survey_buddy/lib/python3.12/site-packages/modal/_utils/grpc_utils.py", line 114, in __connect__
    protocol = await self._create_connection()
               ^^^^^^^^^^^^^^^^^^^^^^^^^^^^^^^
  File "/Users/minkijung/anaconda3/envs/survey_buddy/lib/python3.12/site-packages/grpclib/client.py", line 725, in _create_connection
    _, protocol = await self._loop.create_connection(
                  ^^^^^^^^^^^^^^^^^^^^^^^^^^^^^^^^^^^
  File "/Users/minkijung/anaconda3/envs/survey_buddy/lib/python3.12/asyncio/base_events.py", line 1078, in create_connection
    infos = await self._ensure_resolved(
            ^^^^^^^^^^^^^^^^^^^^^^^^^^^^
  File "/Users/minkijung/anaconda3/envs/survey_buddy/lib/python3.12/asyncio/base_events.py", line 1454, in _ensure_resolved
    return await loop.getaddrinfo(host, port, family=family, type=type,
           ^^^^^^^^^^^^^^^^^^^^^^^^^^^^^^^^^^^^^^^^^^^^^^^^^^^^^^^^^^^^
  File "/Users/minkijung/anaconda3/envs/survey_buddy/lib/python3.12/asyncio/base_events.py", line 899, in getaddrinfo
    return await self.run_in_executor(
                 ^^^^^^^^^^^^^^^^^^^^^
  File "/Users/minkijung/anaconda3/envs/survey_buddy/lib/python3.12/asyncio/base_events.py", line 861, in run_in_executor
    executor.submit(func, *args), loop=self)
    ^^^^^^^^^^^^^^^^^^^^^^^^^^^^
  File "/Users/minkijung/anaconda3/envs/survey_buddy/lib/python3.12/concurrent/futures/thread.py", line 170, in submit
    raise RuntimeError('cannot schedule new futures after shutdown')
RuntimeError: cannot schedule new futures after shutdown
unhandled exception during asyncio.run() shutdown
task: <Task finished name='Task-13' coro=<Resolver.load() done, defined at /Users/minkijung/anaconda3/envs/survey_buddy/lib/python3.12/site-packages/modal/_resolver.py:89> exception=RuntimeError('cannot schedule new futures after shutdown')>
Traceback (most recent call last):
  File "/Users/minkijung/anaconda3/envs/survey_buddy/lib/python3.12/site-packages/modal/_resolver.py", line 149, in load
    return await cached_future
           ^^^^^^^^^^^^^^^^^^^
  File "/Users/minkijung/anaconda3/envs/survey_buddy/lib/python3.12/site-packages/modal/_resolver.py", line 125, in loader
    await obj._load(obj, self, existing_object_id)
  File "/Users/minkijung/anaconda3/envs/survey_buddy/lib/python3.12/site-packages/modal/image.py", line 400, in _load
    await join()
  File "/Users/minkijung/anaconda3/envs/survey_buddy/lib/python3.12/site-packages/modal/image.py", line 383, in join
    async for response in unary_stream(resolver.client.stub.ImageJoinStreaming, request):
  File "/Users/minkijung/anaconda3/envs/survey_buddy/lib/python3.12/site-packages/modal/_utils/grpc_utils.py", line 202, in unary_stream
    await stream.send_message(request, end=True)
  File "/Users/minkijung/anaconda3/envs/survey_buddy/lib/python3.12/site-packages/grpclib/client.py", line 241, in send_message
    await self.send_request()
  File "/Users/minkijung/anaconda3/envs/survey_buddy/lib/python3.12/site-packages/grpclib/client.py", line 173, in send_request
    protocol = await self._channel.__connect__()
               ^^^^^^^^^^^^^^^^^^^^^^^^^^^^^^^^^
  File "/Users/minkijung/anaconda3/envs/survey_buddy/lib/python3.12/site-packages/modal/_utils/grpc_utils.py", line 114, in __connect__
    protocol = await self._create_connection()
               ^^^^^^^^^^^^^^^^^^^^^^^^^^^^^^^
  File "/Users/minkijung/anaconda3/envs/survey_buddy/lib/python3.12/site-packages/grpclib/client.py", line 725, in _create_connection
    _, protocol = await self._loop.create_connection(
                  ^^^^^^^^^^^^^^^^^^^^^^^^^^^^^^^^^^^
  File "/Users/minkijung/anaconda3/envs/survey_buddy/lib/python3.12/asyncio/base_events.py", line 1078, in create_connection
    infos = await self._ensure_resolved(
            ^^^^^^^^^^^^^^^^^^^^^^^^^^^^
  File "/Users/minkijung/anaconda3/envs/survey_buddy/lib/python3.12/asyncio/base_events.py", line 1454, in _ensure_resolved
    return await loop.getaddrinfo(host, port, family=family, type=type,
           ^^^^^^^^^^^^^^^^^^^^^^^^^^^^^^^^^^^^^^^^^^^^^^^^^^^^^^^^^^^^
  File "/Users/minkijung/anaconda3/envs/survey_buddy/lib/python3.12/asyncio/base_events.py", line 899, in getaddrinfo
    return await self.run_in_executor(
                 ^^^^^^^^^^^^^^^^^^^^^
  File "/Users/minkijung/anaconda3/envs/survey_buddy/lib/python3.12/asyncio/base_events.py", line 861, in run_in_executor
    executor.submit(func, *args), loop=self)
    ^^^^^^^^^^^^^^^^^^^^^^^^^^^^
  File "/Users/minkijung/anaconda3/envs/survey_buddy/lib/python3.12/concurrent/futures/thread.py", line 170, in submit
    raise RuntimeError('cannot schedule new futures after shutdown')
RuntimeError: cannot schedule new futures after shutdown
1 change detected
1 change detected
1 change detected
1 change detected
1 change detected
2 changes detected
1 change detected
1 change detected
1 change detected
1 change detected
1 change detected
2 changes detected
1 change detected
2 changes detected
1 change detected
1 change detected
1 change detected
Mount of 'PythonPackage:datasets_modules' is empty.
1 change detected
Mount of 'PythonPackage:datasets_modules' is empty.
1 change detected
Mount of 'PythonPackage:datasets_modules' is empty.
1 change detected
2 changes detected
Mount of 'PythonPackage:datasets_modules' is empty.
1 change detected
1 change detected
4 changes detected
1 change detected
2 changes detected
2 changes detected
1 change detected
1 change detected
6 changes detected
1 change detected
2 changes detected
