Mount of 'PythonPackage:datasets_modules' is empty.
1 change detected
2 changes detected
2 changes detected
2 changes detected
2 changes detected
2 changes detected
2 changes detected
2 changes detected
1 change detected
1 change detected
1 change detected
2 changes detected
2 changes detected
3 changes detected
2 changes detected
1 change detected
1 change detected
1 change detected
1 change detected
1 change detected
1 change detected
1 change detected
1 change detected
2 changes detected
1 change detected
1 change detected
1 change detected
1 change detected
1 change detected
1 change detected
1 change detected
1 change detected
2 changes detected
1 change detected
1 change detected
2 changes detected
1 change detected
1 change detected
1 change detected
1 change detected
1 change detected
1 change detected
1 change detected
1 change detected
3 changes detected
1 change detected
1 change detected
1 change detected
1 change detected
1 change detected
1 change detected
1 change detected
1 change detected
1 change detected
1 change detected
2 changes detected
1 change detected
1 change detected
2 changes detected
1 change detected
1 change detected
1 change detected
1 change detected
2 changes detected
1 change detected
1 change detected
1 change detected
1 change detected
1 change detected
unhandled exception during asyncio.run() shutdown
task: <Task finished name='Task-2' coro=<Synchronizer._wrap_check_async_leakage.<locals>.coro_wrapped() done, defined at /Users/minkijung/anaconda3/envs/survey_buddy/lib/python3.12/site-packages/synchronicity/synchronizer.py:214> exception=UserCodeException(RuntimeError('cannot schedule new futures after shutdown'))>
Traceback (most recent call last):
  File "/Users/minkijung/anaconda3/envs/survey_buddy/lib/python3.12/site-packages/modal/runner.py", line 327, in _serve_update
    await _create_all_objects(
  File "/Users/minkijung/anaconda3/envs/survey_buddy/lib/python3.12/site-packages/modal/runner.py", line 137, in _create_all_objects
    await resolver.load(obj, existing_object_id)
  File "/Users/minkijung/anaconda3/envs/survey_buddy/lib/python3.12/site-packages/modal/_resolver.py", line 149, in load
    return await cached_future
           ^^^^^^^^^^^^^^^^^^^
  File "/Users/minkijung/anaconda3/envs/survey_buddy/lib/python3.12/site-packages/modal/_resolver.py", line 121, in loader
    await asyncio.gather(*[self.load(dep) for dep in obj.deps()])
  File "/Users/minkijung/anaconda3/envs/survey_buddy/lib/python3.12/site-packages/modal/_resolver.py", line 149, in load
    return await cached_future
           ^^^^^^^^^^^^^^^^^^^
  File "/Users/minkijung/anaconda3/envs/survey_buddy/lib/python3.12/site-packages/modal/_resolver.py", line 125, in loader
    await obj._load(obj, self, existing_object_id)
  File "/Users/minkijung/anaconda3/envs/survey_buddy/lib/python3.12/site-packages/modal/image.py", line 400, in _load
    await join()
  File "/Users/minkijung/anaconda3/envs/survey_buddy/lib/python3.12/site-packages/modal/image.py", line 383, in join
    async for response in unary_stream(resolver.client.stub.ImageJoinStreaming, request):
  File "/Users/minkijung/anaconda3/envs/survey_buddy/lib/python3.12/site-packages/modal/_utils/grpc_utils.py", line 202, in unary_stream
    await stream.send_message(request, end=True)
  File "/Users/minkijung/anaconda3/envs/survey_buddy/lib/python3.12/site-packages/grpclib/client.py", line 241, in send_message
    await self.send_request()
  File "/Users/minkijung/anaconda3/envs/survey_buddy/lib/python3.12/site-packages/grpclib/client.py", line 173, in send_request
    protocol = await self._channel.__connect__()
               ^^^^^^^^^^^^^^^^^^^^^^^^^^^^^^^^^
  File "/Users/minkijung/anaconda3/envs/survey_buddy/lib/python3.12/site-packages/modal/_utils/grpc_utils.py", line 114, in __connect__
    protocol = await self._create_connection()
               ^^^^^^^^^^^^^^^^^^^^^^^^^^^^^^^
  File "/Users/minkijung/anaconda3/envs/survey_buddy/lib/python3.12/site-packages/grpclib/client.py", line 725, in _create_connection
    _, protocol = await self._loop.create_connection(
                  ^^^^^^^^^^^^^^^^^^^^^^^^^^^^^^^^^^^
  File "/Users/minkijung/anaconda3/envs/survey_buddy/lib/python3.12/asyncio/base_events.py", line 1078, in create_connection
    infos = await self._ensure_resolved(
            ^^^^^^^^^^^^^^^^^^^^^^^^^^^^
  File "/Users/minkijung/anaconda3/envs/survey_buddy/lib/python3.12/asyncio/base_events.py", line 1454, in _ensure_resolved
    return await loop.getaddrinfo(host, port, family=family, type=type,
           ^^^^^^^^^^^^^^^^^^^^^^^^^^^^^^^^^^^^^^^^^^^^^^^^^^^^^^^^^^^^
  File "/Users/minkijung/anaconda3/envs/survey_buddy/lib/python3.12/asyncio/base_events.py", line 899, in getaddrinfo
    return await self.run_in_executor(
                 ^^^^^^^^^^^^^^^^^^^^^
  File "/Users/minkijung/anaconda3/envs/survey_buddy/lib/python3.12/asyncio/base_events.py", line 861, in run_in_executor
    executor.submit(func, *args), loop=self)
    ^^^^^^^^^^^^^^^^^^^^^^^^^^^^
  File "/Users/minkijung/anaconda3/envs/survey_buddy/lib/python3.12/concurrent/futures/thread.py", line 170, in submit
    raise RuntimeError('cannot schedule new futures after shutdown')
RuntimeError: cannot schedule new futures after shutdown

During handling of the above exception, another exception occurred:

Traceback (most recent call last):
  File "/Users/minkijung/anaconda3/envs/survey_buddy/lib/python3.12/site-packages/synchronicity/synchronizer.py", line 215, in coro_wrapped
    value = await coro
            ^^^^^^^^^^
  File "/Users/minkijung/anaconda3/envs/survey_buddy/lib/python3.12/site-packages/synchronicity/exceptions.py", line 31, in coro_wrapped
    raise UserCodeException(exc)
synchronicity.exceptions.UserCodeException: cannot schedule new futures after shutdown
unhandled exception during asyncio.run() shutdown
task: <Task finished name='Task-4' coro=<Resolver.load.<locals>.loader() done, defined at /Users/minkijung/anaconda3/envs/survey_buddy/lib/python3.12/site-packages/modal/_resolver.py:118> exception=RuntimeError('cannot schedule new futures after shutdown')>
Traceback (most recent call last):
  File "/Users/minkijung/anaconda3/envs/survey_buddy/lib/python3.12/site-packages/modal/runner.py", line 327, in _serve_update
    await _create_all_objects(
  File "/Users/minkijung/anaconda3/envs/survey_buddy/lib/python3.12/site-packages/modal/runner.py", line 137, in _create_all_objects
    await resolver.load(obj, existing_object_id)
  File "/Users/minkijung/anaconda3/envs/survey_buddy/lib/python3.12/site-packages/modal/_resolver.py", line 149, in load
    return await cached_future
           ^^^^^^^^^^^^^^^^^^^
  File "/Users/minkijung/anaconda3/envs/survey_buddy/lib/python3.12/site-packages/modal/_resolver.py", line 121, in loader
    await asyncio.gather(*[self.load(dep) for dep in obj.deps()])
  File "/Users/minkijung/anaconda3/envs/survey_buddy/lib/python3.12/site-packages/modal/_resolver.py", line 149, in load
    return await cached_future
           ^^^^^^^^^^^^^^^^^^^
  File "/Users/minkijung/anaconda3/envs/survey_buddy/lib/python3.12/site-packages/modal/_resolver.py", line 125, in loader
    await obj._load(obj, self, existing_object_id)
  File "/Users/minkijung/anaconda3/envs/survey_buddy/lib/python3.12/site-packages/modal/image.py", line 400, in _load
    await join()
  File "/Users/minkijung/anaconda3/envs/survey_buddy/lib/python3.12/site-packages/modal/image.py", line 383, in join
    async for response in unary_stream(resolver.client.stub.ImageJoinStreaming, request):
  File "/Users/minkijung/anaconda3/envs/survey_buddy/lib/python3.12/site-packages/modal/_utils/grpc_utils.py", line 202, in unary_stream
    await stream.send_message(request, end=True)
  File "/Users/minkijung/anaconda3/envs/survey_buddy/lib/python3.12/site-packages/grpclib/client.py", line 241, in send_message
    await self.send_request()
  File "/Users/minkijung/anaconda3/envs/survey_buddy/lib/python3.12/site-packages/grpclib/client.py", line 173, in send_request
    protocol = await self._channel.__connect__()
               ^^^^^^^^^^^^^^^^^^^^^^^^^^^^^^^^^
  File "/Users/minkijung/anaconda3/envs/survey_buddy/lib/python3.12/site-packages/modal/_utils/grpc_utils.py", line 114, in __connect__
    protocol = await self._create_connection()
               ^^^^^^^^^^^^^^^^^^^^^^^^^^^^^^^
  File "/Users/minkijung/anaconda3/envs/survey_buddy/lib/python3.12/site-packages/grpclib/client.py", line 725, in _create_connection
    _, protocol = await self._loop.create_connection(
                  ^^^^^^^^^^^^^^^^^^^^^^^^^^^^^^^^^^^
  File "/Users/minkijung/anaconda3/envs/survey_buddy/lib/python3.12/asyncio/base_events.py", line 1078, in create_connection
    infos = await self._ensure_resolved(
            ^^^^^^^^^^^^^^^^^^^^^^^^^^^^
  File "/Users/minkijung/anaconda3/envs/survey_buddy/lib/python3.12/asyncio/base_events.py", line 1454, in _ensure_resolved
    return await loop.getaddrinfo(host, port, family=family, type=type,
           ^^^^^^^^^^^^^^^^^^^^^^^^^^^^^^^^^^^^^^^^^^^^^^^^^^^^^^^^^^^^
  File "/Users/minkijung/anaconda3/envs/survey_buddy/lib/python3.12/asyncio/base_events.py", line 899, in getaddrinfo
    return await self.run_in_executor(
                 ^^^^^^^^^^^^^^^^^^^^^
  File "/Users/minkijung/anaconda3/envs/survey_buddy/lib/python3.12/asyncio/base_events.py", line 861, in run_in_executor
    executor.submit(func, *args), loop=self)
    ^^^^^^^^^^^^^^^^^^^^^^^^^^^^
  File "/Users/minkijung/anaconda3/envs/survey_buddy/lib/python3.12/concurrent/futures/thread.py", line 170, in submit
    raise RuntimeError('cannot schedule new futures after shutdown')
RuntimeError: cannot schedule new futures after shutdown
unhandled exception during asyncio.run() shutdown
task: <Task finished name='Task-11' coro=<Resolver.load.<locals>.loader() done, defined at /Users/minkijung/anaconda3/envs/survey_buddy/lib/python3.12/site-packages/modal/_resolver.py:118> exception=RuntimeError('cannot schedule new futures after shutdown')>
Traceback (most recent call last):
  File "/Users/minkijung/anaconda3/envs/survey_buddy/lib/python3.12/site-packages/modal/runner.py", line 327, in _serve_update
    await _create_all_objects(
  File "/Users/minkijung/anaconda3/envs/survey_buddy/lib/python3.12/site-packages/modal/runner.py", line 137, in _create_all_objects
    await resolver.load(obj, existing_object_id)
  File "/Users/minkijung/anaconda3/envs/survey_buddy/lib/python3.12/site-packages/modal/_resolver.py", line 149, in load
    return await cached_future
           ^^^^^^^^^^^^^^^^^^^
  File "/Users/minkijung/anaconda3/envs/survey_buddy/lib/python3.12/site-packages/modal/_resolver.py", line 121, in loader
    await asyncio.gather(*[self.load(dep) for dep in obj.deps()])
  File "/Users/minkijung/anaconda3/envs/survey_buddy/lib/python3.12/site-packages/modal/_resolver.py", line 149, in load
    return await cached_future
           ^^^^^^^^^^^^^^^^^^^
  File "/Users/minkijung/anaconda3/envs/survey_buddy/lib/python3.12/site-packages/modal/_resolver.py", line 125, in loader
    await obj._load(obj, self, existing_object_id)
  File "/Users/minkijung/anaconda3/envs/survey_buddy/lib/python3.12/site-packages/modal/image.py", line 400, in _load
    await join()
  File "/Users/minkijung/anaconda3/envs/survey_buddy/lib/python3.12/site-packages/modal/image.py", line 383, in join
    async for response in unary_stream(resolver.client.stub.ImageJoinStreaming, request):
  File "/Users/minkijung/anaconda3/envs/survey_buddy/lib/python3.12/site-packages/modal/_utils/grpc_utils.py", line 202, in unary_stream
    await stream.send_message(request, end=True)
  File "/Users/minkijung/anaconda3/envs/survey_buddy/lib/python3.12/site-packages/grpclib/client.py", line 241, in send_message
    await self.send_request()
  File "/Users/minkijung/anaconda3/envs/survey_buddy/lib/python3.12/site-packages/grpclib/client.py", line 173, in send_request
    protocol = await self._channel.__connect__()
               ^^^^^^^^^^^^^^^^^^^^^^^^^^^^^^^^^
  File "/Users/minkijung/anaconda3/envs/survey_buddy/lib/python3.12/site-packages/modal/_utils/grpc_utils.py", line 114, in __connect__
    protocol = await self._create_connection()
               ^^^^^^^^^^^^^^^^^^^^^^^^^^^^^^^
  File "/Users/minkijung/anaconda3/envs/survey_buddy/lib/python3.12/site-packages/grpclib/client.py", line 725, in _create_connection
    _, protocol = await self._loop.create_connection(
                  ^^^^^^^^^^^^^^^^^^^^^^^^^^^^^^^^^^^
  File "/Users/minkijung/anaconda3/envs/survey_buddy/lib/python3.12/asyncio/base_events.py", line 1078, in create_connection
    infos = await self._ensure_resolved(
            ^^^^^^^^^^^^^^^^^^^^^^^^^^^^
  File "/Users/minkijung/anaconda3/envs/survey_buddy/lib/python3.12/asyncio/base_events.py", line 1454, in _ensure_resolved
    return await loop.getaddrinfo(host, port, family=family, type=type,
           ^^^^^^^^^^^^^^^^^^^^^^^^^^^^^^^^^^^^^^^^^^^^^^^^^^^^^^^^^^^^
  File "/Users/minkijung/anaconda3/envs/survey_buddy/lib/python3.12/asyncio/base_events.py", line 899, in getaddrinfo
    return await self.run_in_executor(
                 ^^^^^^^^^^^^^^^^^^^^^
  File "/Users/minkijung/anaconda3/envs/survey_buddy/lib/python3.12/asyncio/base_events.py", line 861, in run_in_executor
    executor.submit(func, *args), loop=self)
    ^^^^^^^^^^^^^^^^^^^^^^^^^^^^
  File "/Users/minkijung/anaconda3/envs/survey_buddy/lib/python3.12/concurrent/futures/thread.py", line 170, in submit
    raise RuntimeError('cannot schedule new futures after shutdown')
RuntimeError: cannot schedule new futures after shutdown
unhandled exception during asyncio.run() shutdown
task: <Task finished name='Task-8' coro=<Resolver.load() done, defined at /Users/minkijung/anaconda3/envs/survey_buddy/lib/python3.12/site-packages/modal/_resolver.py:89> exception=RuntimeError('cannot schedule new futures after shutdown')>
Traceback (most recent call last):
  File "/Users/minkijung/anaconda3/envs/survey_buddy/lib/python3.12/site-packages/modal/runner.py", line 327, in _serve_update
    await _create_all_objects(
  File "/Users/minkijung/anaconda3/envs/survey_buddy/lib/python3.12/site-packages/modal/runner.py", line 137, in _create_all_objects
    await resolver.load(obj, existing_object_id)
  File "/Users/minkijung/anaconda3/envs/survey_buddy/lib/python3.12/site-packages/modal/_resolver.py", line 149, in load
    return await cached_future
           ^^^^^^^^^^^^^^^^^^^
  File "/Users/minkijung/anaconda3/envs/survey_buddy/lib/python3.12/site-packages/modal/_resolver.py", line 121, in loader
    await asyncio.gather(*[self.load(dep) for dep in obj.deps()])
  File "/Users/minkijung/anaconda3/envs/survey_buddy/lib/python3.12/site-packages/modal/_resolver.py", line 149, in load
    return await cached_future
           ^^^^^^^^^^^^^^^^^^^
  File "/Users/minkijung/anaconda3/envs/survey_buddy/lib/python3.12/site-packages/modal/_resolver.py", line 125, in loader
    await obj._load(obj, self, existing_object_id)
  File "/Users/minkijung/anaconda3/envs/survey_buddy/lib/python3.12/site-packages/modal/image.py", line 400, in _load
    await join()
  File "/Users/minkijung/anaconda3/envs/survey_buddy/lib/python3.12/site-packages/modal/image.py", line 383, in join
    async for response in unary_stream(resolver.client.stub.ImageJoinStreaming, request):
  File "/Users/minkijung/anaconda3/envs/survey_buddy/lib/python3.12/site-packages/modal/_utils/grpc_utils.py", line 202, in unary_stream
    await stream.send_message(request, end=True)
  File "/Users/minkijung/anaconda3/envs/survey_buddy/lib/python3.12/site-packages/grpclib/client.py", line 241, in send_message
    await self.send_request()
  File "/Users/minkijung/anaconda3/envs/survey_buddy/lib/python3.12/site-packages/grpclib/client.py", line 173, in send_request
    protocol = await self._channel.__connect__()
               ^^^^^^^^^^^^^^^^^^^^^^^^^^^^^^^^^
  File "/Users/minkijung/anaconda3/envs/survey_buddy/lib/python3.12/site-packages/modal/_utils/grpc_utils.py", line 114, in __connect__
    protocol = await self._create_connection()
               ^^^^^^^^^^^^^^^^^^^^^^^^^^^^^^^
  File "/Users/minkijung/anaconda3/envs/survey_buddy/lib/python3.12/site-packages/grpclib/client.py", line 725, in _create_connection
    _, protocol = await self._loop.create_connection(
                  ^^^^^^^^^^^^^^^^^^^^^^^^^^^^^^^^^^^
  File "/Users/minkijung/anaconda3/envs/survey_buddy/lib/python3.12/asyncio/base_events.py", line 1078, in create_connection
    infos = await self._ensure_resolved(
            ^^^^^^^^^^^^^^^^^^^^^^^^^^^^
  File "/Users/minkijung/anaconda3/envs/survey_buddy/lib/python3.12/asyncio/base_events.py", line 1454, in _ensure_resolved
    return await loop.getaddrinfo(host, port, family=family, type=type,
           ^^^^^^^^^^^^^^^^^^^^^^^^^^^^^^^^^^^^^^^^^^^^^^^^^^^^^^^^^^^^
  File "/Users/minkijung/anaconda3/envs/survey_buddy/lib/python3.12/asyncio/base_events.py", line 899, in getaddrinfo
    return await self.run_in_executor(
                 ^^^^^^^^^^^^^^^^^^^^^
  File "/Users/minkijung/anaconda3/envs/survey_buddy/lib/python3.12/asyncio/base_events.py", line 861, in run_in_executor
    executor.submit(func, *args), loop=self)
    ^^^^^^^^^^^^^^^^^^^^^^^^^^^^
  File "/Users/minkijung/anaconda3/envs/survey_buddy/lib/python3.12/concurrent/futures/thread.py", line 170, in submit
    raise RuntimeError('cannot schedule new futures after shutdown')
RuntimeError: cannot schedule new futures after shutdown
unhandled exception during asyncio.run() shutdown
task: <Task finished name='Task-13' coro=<Resolver.load.<locals>.loader() done, defined at /Users/minkijung/anaconda3/envs/survey_buddy/lib/python3.12/site-packages/modal/_resolver.py:118> exception=RuntimeError('cannot schedule new futures after shutdown')>
Traceback (most recent call last):
  File "/Users/minkijung/anaconda3/envs/survey_buddy/lib/python3.12/site-packages/modal/runner.py", line 289, in _run_stub
    raise e
  File "/Users/minkijung/anaconda3/envs/survey_buddy/lib/python3.12/site-packages/modal/runner.py", line 243, in _run_stub
    await _create_all_objects(
  File "/Users/minkijung/anaconda3/envs/survey_buddy/lib/python3.12/site-packages/modal/runner.py", line 137, in _create_all_objects
    await resolver.load(obj, existing_object_id)
  File "/Users/minkijung/anaconda3/envs/survey_buddy/lib/python3.12/site-packages/modal/_resolver.py", line 149, in load
    return await cached_future
           ^^^^^^^^^^^^^^^^^^^
  File "/Users/minkijung/anaconda3/envs/survey_buddy/lib/python3.12/site-packages/modal/_resolver.py", line 121, in loader
    await asyncio.gather(*[self.load(dep) for dep in obj.deps()])
  File "/Users/minkijung/anaconda3/envs/survey_buddy/lib/python3.12/site-packages/modal/_resolver.py", line 149, in load
    return await cached_future
           ^^^^^^^^^^^^^^^^^^^
  File "/Users/minkijung/anaconda3/envs/survey_buddy/lib/python3.12/site-packages/modal/_resolver.py", line 125, in loader
    await obj._load(obj, self, existing_object_id)
  File "/Users/minkijung/anaconda3/envs/survey_buddy/lib/python3.12/site-packages/modal/image.py", line 400, in _load
    await join()
  File "/Users/minkijung/anaconda3/envs/survey_buddy/lib/python3.12/site-packages/modal/image.py", line 383, in join
    async for response in unary_stream(resolver.client.stub.ImageJoinStreaming, request):
  File "/Users/minkijung/anaconda3/envs/survey_buddy/lib/python3.12/site-packages/modal/_utils/grpc_utils.py", line 202, in unary_stream
    await stream.send_message(request, end=True)
  File "/Users/minkijung/anaconda3/envs/survey_buddy/lib/python3.12/site-packages/grpclib/client.py", line 241, in send_message
    await self.send_request()
  File "/Users/minkijung/anaconda3/envs/survey_buddy/lib/python3.12/site-packages/grpclib/client.py", line 173, in send_request
    protocol = await self._channel.__connect__()
               ^^^^^^^^^^^^^^^^^^^^^^^^^^^^^^^^^
  File "/Users/minkijung/anaconda3/envs/survey_buddy/lib/python3.12/site-packages/modal/_utils/grpc_utils.py", line 114, in __connect__
    protocol = await self._create_connection()
               ^^^^^^^^^^^^^^^^^^^^^^^^^^^^^^^
  File "/Users/minkijung/anaconda3/envs/survey_buddy/lib/python3.12/site-packages/grpclib/client.py", line 725, in _create_connection
    _, protocol = await self._loop.create_connection(
                  ^^^^^^^^^^^^^^^^^^^^^^^^^^^^^^^^^^^
  File "/Users/minkijung/anaconda3/envs/survey_buddy/lib/python3.12/asyncio/base_events.py", line 1078, in create_connection
    infos = await self._ensure_resolved(
            ^^^^^^^^^^^^^^^^^^^^^^^^^^^^
  File "/Users/minkijung/anaconda3/envs/survey_buddy/lib/python3.12/asyncio/base_events.py", line 1454, in _ensure_resolved
    return await loop.getaddrinfo(host, port, family=family, type=type,
           ^^^^^^^^^^^^^^^^^^^^^^^^^^^^^^^^^^^^^^^^^^^^^^^^^^^^^^^^^^^^
  File "/Users/minkijung/anaconda3/envs/survey_buddy/lib/python3.12/asyncio/base_events.py", line 899, in getaddrinfo
    return await self.run_in_executor(
                 ^^^^^^^^^^^^^^^^^^^^^
  File "/Users/minkijung/anaconda3/envs/survey_buddy/lib/python3.12/asyncio/base_events.py", line 861, in run_in_executor
    executor.submit(func, *args), loop=self)
    ^^^^^^^^^^^^^^^^^^^^^^^^^^^^
  File "/Users/minkijung/anaconda3/envs/survey_buddy/lib/python3.12/concurrent/futures/thread.py", line 170, in submit
    raise RuntimeError('cannot schedule new futures after shutdown')
RuntimeError: cannot schedule new futures after shutdown
unhandled exception during asyncio.run() shutdown
task: <Task finished name='Task-2' coro=<Synchronizer._wrap_check_async_leakage.<locals>.coro_wrapped() done, defined at /Users/minkijung/anaconda3/envs/survey_buddy/lib/python3.12/site-packages/synchronicity/synchronizer.py:214> exception=UserCodeException(RuntimeError('cannot schedule new futures after shutdown'))>
Traceback (most recent call last):
  File "/Users/minkijung/anaconda3/envs/survey_buddy/lib/python3.12/site-packages/modal/runner.py", line 289, in _run_stub
    raise e
  File "/Users/minkijung/anaconda3/envs/survey_buddy/lib/python3.12/site-packages/modal/runner.py", line 243, in _run_stub
    await _create_all_objects(
  File "/Users/minkijung/anaconda3/envs/survey_buddy/lib/python3.12/site-packages/modal/runner.py", line 137, in _create_all_objects
    await resolver.load(obj, existing_object_id)
  File "/Users/minkijung/anaconda3/envs/survey_buddy/lib/python3.12/site-packages/modal/_resolver.py", line 149, in load
    return await cached_future
           ^^^^^^^^^^^^^^^^^^^
  File "/Users/minkijung/anaconda3/envs/survey_buddy/lib/python3.12/site-packages/modal/_resolver.py", line 121, in loader
    await asyncio.gather(*[self.load(dep) for dep in obj.deps()])
  File "/Users/minkijung/anaconda3/envs/survey_buddy/lib/python3.12/site-packages/modal/_resolver.py", line 149, in load
    return await cached_future
           ^^^^^^^^^^^^^^^^^^^
  File "/Users/minkijung/anaconda3/envs/survey_buddy/lib/python3.12/site-packages/modal/_resolver.py", line 125, in loader
    await obj._load(obj, self, existing_object_id)
  File "/Users/minkijung/anaconda3/envs/survey_buddy/lib/python3.12/site-packages/modal/image.py", line 400, in _load
    await join()
  File "/Users/minkijung/anaconda3/envs/survey_buddy/lib/python3.12/site-packages/modal/image.py", line 383, in join
    async for response in unary_stream(resolver.client.stub.ImageJoinStreaming, request):
  File "/Users/minkijung/anaconda3/envs/survey_buddy/lib/python3.12/site-packages/modal/_utils/grpc_utils.py", line 202, in unary_stream
    await stream.send_message(request, end=True)
  File "/Users/minkijung/anaconda3/envs/survey_buddy/lib/python3.12/site-packages/grpclib/client.py", line 241, in send_message
    await self.send_request()
  File "/Users/minkijung/anaconda3/envs/survey_buddy/lib/python3.12/site-packages/grpclib/client.py", line 173, in send_request
    protocol = await self._channel.__connect__()
               ^^^^^^^^^^^^^^^^^^^^^^^^^^^^^^^^^
  File "/Users/minkijung/anaconda3/envs/survey_buddy/lib/python3.12/site-packages/modal/_utils/grpc_utils.py", line 114, in __connect__
    protocol = await self._create_connection()
               ^^^^^^^^^^^^^^^^^^^^^^^^^^^^^^^
  File "/Users/minkijung/anaconda3/envs/survey_buddy/lib/python3.12/site-packages/grpclib/client.py", line 725, in _create_connection
    _, protocol = await self._loop.create_connection(
                  ^^^^^^^^^^^^^^^^^^^^^^^^^^^^^^^^^^^
  File "/Users/minkijung/anaconda3/envs/survey_buddy/lib/python3.12/asyncio/base_events.py", line 1078, in create_connection
    infos = await self._ensure_resolved(
            ^^^^^^^^^^^^^^^^^^^^^^^^^^^^
  File "/Users/minkijung/anaconda3/envs/survey_buddy/lib/python3.12/asyncio/base_events.py", line 1454, in _ensure_resolved
    return await loop.getaddrinfo(host, port, family=family, type=type,
           ^^^^^^^^^^^^^^^^^^^^^^^^^^^^^^^^^^^^^^^^^^^^^^^^^^^^^^^^^^^^
  File "/Users/minkijung/anaconda3/envs/survey_buddy/lib/python3.12/asyncio/base_events.py", line 899, in getaddrinfo
    return await self.run_in_executor(
                 ^^^^^^^^^^^^^^^^^^^^^
  File "/Users/minkijung/anaconda3/envs/survey_buddy/lib/python3.12/asyncio/base_events.py", line 861, in run_in_executor
    executor.submit(func, *args), loop=self)
    ^^^^^^^^^^^^^^^^^^^^^^^^^^^^
  File "/Users/minkijung/anaconda3/envs/survey_buddy/lib/python3.12/concurrent/futures/thread.py", line 170, in submit
    raise RuntimeError('cannot schedule new futures after shutdown')
RuntimeError: cannot schedule new futures after shutdown

During handling of the above exception, another exception occurred:

Traceback (most recent call last):
  File "/Users/minkijung/anaconda3/envs/survey_buddy/lib/python3.12/contextlib.py", line 210, in __aenter__
    return await anext(self.gen)
           ^^^^^^^^^^^^^^^^^^^^^
  File "/Users/minkijung/anaconda3/envs/survey_buddy/lib/python3.12/site-packages/modal/serving.py", line 123, in _serve_stub
    async with _run_stub(stub, client=client, output_mgr=output_mgr, environment_name=environment_name):
  File "/Users/minkijung/anaconda3/envs/survey_buddy/lib/python3.12/contextlib.py", line 210, in __aenter__
    return await anext(self.gen)
           ^^^^^^^^^^^^^^^^^^^^^
  File "/Users/minkijung/anaconda3/envs/survey_buddy/lib/python3.12/site-packages/modal/runner.py", line 305, in _run_stub
    await _disconnect(client, app.app_id, reason, exc_str)
  File "/Users/minkijung/anaconda3/envs/survey_buddy/lib/python3.12/site-packages/modal/runner.py", line 171, in _disconnect
    await retry_transient_errors(client.stub.AppClientDisconnect, req_disconnect)
  File "/Users/minkijung/anaconda3/envs/survey_buddy/lib/python3.12/site-packages/modal/_utils/grpc_utils.py", line 249, in retry_transient_errors
    return await fn(*args, metadata=metadata, timeout=timeout)
           ^^^^^^^^^^^^^^^^^^^^^^^^^^^^^^^^^^^^^^^^^^^^^^^^^^^
  File "/Users/minkijung/anaconda3/envs/survey_buddy/lib/python3.12/site-packages/grpclib/client.py", line 903, in __call__
    await stream.send_message(message, end=True)
  File "/Users/minkijung/anaconda3/envs/survey_buddy/lib/python3.12/site-packages/grpclib/client.py", line 241, in send_message
    await self.send_request()
  File "/Users/minkijung/anaconda3/envs/survey_buddy/lib/python3.12/site-packages/grpclib/client.py", line 173, in send_request
    protocol = await self._channel.__connect__()
               ^^^^^^^^^^^^^^^^^^^^^^^^^^^^^^^^^
  File "/Users/minkijung/anaconda3/envs/survey_buddy/lib/python3.12/site-packages/modal/_utils/grpc_utils.py", line 114, in __connect__
    protocol = await self._create_connection()
               ^^^^^^^^^^^^^^^^^^^^^^^^^^^^^^^
  File "/Users/minkijung/anaconda3/envs/survey_buddy/lib/python3.12/site-packages/grpclib/client.py", line 725, in _create_connection
    _, protocol = await self._loop.create_connection(
                  ^^^^^^^^^^^^^^^^^^^^^^^^^^^^^^^^^^^
  File "/Users/minkijung/anaconda3/envs/survey_buddy/lib/python3.12/asyncio/base_events.py", line 1078, in create_connection
    infos = await self._ensure_resolved(
            ^^^^^^^^^^^^^^^^^^^^^^^^^^^^
  File "/Users/minkijung/anaconda3/envs/survey_buddy/lib/python3.12/asyncio/base_events.py", line 1454, in _ensure_resolved
    return await loop.getaddrinfo(host, port, family=family, type=type,
           ^^^^^^^^^^^^^^^^^^^^^^^^^^^^^^^^^^^^^^^^^^^^^^^^^^^^^^^^^^^^
  File "/Users/minkijung/anaconda3/envs/survey_buddy/lib/python3.12/asyncio/base_events.py", line 899, in getaddrinfo
    return await self.run_in_executor(
                 ^^^^^^^^^^^^^^^^^^^^^
  File "/Users/minkijung/anaconda3/envs/survey_buddy/lib/python3.12/asyncio/base_events.py", line 861, in run_in_executor
    executor.submit(func, *args), loop=self)
    ^^^^^^^^^^^^^^^^^^^^^^^^^^^^
  File "/Users/minkijung/anaconda3/envs/survey_buddy/lib/python3.12/concurrent/futures/thread.py", line 170, in submit
    raise RuntimeError('cannot schedule new futures after shutdown')
RuntimeError: cannot schedule new futures after shutdown

During handling of the above exception, another exception occurred:

Traceback (most recent call last):
  File "/Users/minkijung/anaconda3/envs/survey_buddy/lib/python3.12/site-packages/synchronicity/synchronizer.py", line 215, in coro_wrapped
    value = await coro
            ^^^^^^^^^^
  File "/Users/minkijung/anaconda3/envs/survey_buddy/lib/python3.12/site-packages/synchronicity/exceptions.py", line 31, in coro_wrapped
    raise UserCodeException(exc)
synchronicity.exceptions.UserCodeException: cannot schedule new futures after shutdown
unhandled exception during asyncio.run() shutdown
task: <Task finished name='Task-10' coro=<Resolver.load() done, defined at /Users/minkijung/anaconda3/envs/survey_buddy/lib/python3.12/site-packages/modal/_resolver.py:89> exception=RuntimeError('cannot schedule new futures after shutdown')>
Traceback (most recent call last):
  File "/Users/minkijung/anaconda3/envs/survey_buddy/lib/python3.12/site-packages/modal/runner.py", line 289, in _run_stub
    raise e
  File "/Users/minkijung/anaconda3/envs/survey_buddy/lib/python3.12/site-packages/modal/runner.py", line 243, in _run_stub
    await _create_all_objects(
  File "/Users/minkijung/anaconda3/envs/survey_buddy/lib/python3.12/site-packages/modal/runner.py", line 137, in _create_all_objects
    await resolver.load(obj, existing_object_id)
  File "/Users/minkijung/anaconda3/envs/survey_buddy/lib/python3.12/site-packages/modal/_resolver.py", line 149, in load
    return await cached_future
           ^^^^^^^^^^^^^^^^^^^
  File "/Users/minkijung/anaconda3/envs/survey_buddy/lib/python3.12/site-packages/modal/_resolver.py", line 121, in loader
    await asyncio.gather(*[self.load(dep) for dep in obj.deps()])
  File "/Users/minkijung/anaconda3/envs/survey_buddy/lib/python3.12/site-packages/modal/_resolver.py", line 149, in load
    return await cached_future
           ^^^^^^^^^^^^^^^^^^^
  File "/Users/minkijung/anaconda3/envs/survey_buddy/lib/python3.12/site-packages/modal/_resolver.py", line 125, in loader
    await obj._load(obj, self, existing_object_id)
  File "/Users/minkijung/anaconda3/envs/survey_buddy/lib/python3.12/site-packages/modal/image.py", line 400, in _load
    await join()
  File "/Users/minkijung/anaconda3/envs/survey_buddy/lib/python3.12/site-packages/modal/image.py", line 383, in join
    async for response in unary_stream(resolver.client.stub.ImageJoinStreaming, request):
  File "/Users/minkijung/anaconda3/envs/survey_buddy/lib/python3.12/site-packages/modal/_utils/grpc_utils.py", line 202, in unary_stream
    await stream.send_message(request, end=True)
  File "/Users/minkijung/anaconda3/envs/survey_buddy/lib/python3.12/site-packages/grpclib/client.py", line 241, in send_message
    await self.send_request()
  File "/Users/minkijung/anaconda3/envs/survey_buddy/lib/python3.12/site-packages/grpclib/client.py", line 173, in send_request
    protocol = await self._channel.__connect__()
               ^^^^^^^^^^^^^^^^^^^^^^^^^^^^^^^^^
  File "/Users/minkijung/anaconda3/envs/survey_buddy/lib/python3.12/site-packages/modal/_utils/grpc_utils.py", line 114, in __connect__
    protocol = await self._create_connection()
               ^^^^^^^^^^^^^^^^^^^^^^^^^^^^^^^
  File "/Users/minkijung/anaconda3/envs/survey_buddy/lib/python3.12/site-packages/grpclib/client.py", line 725, in _create_connection
    _, protocol = await self._loop.create_connection(
                  ^^^^^^^^^^^^^^^^^^^^^^^^^^^^^^^^^^^
  File "/Users/minkijung/anaconda3/envs/survey_buddy/lib/python3.12/asyncio/base_events.py", line 1078, in create_connection
    infos = await self._ensure_resolved(
            ^^^^^^^^^^^^^^^^^^^^^^^^^^^^
  File "/Users/minkijung/anaconda3/envs/survey_buddy/lib/python3.12/asyncio/base_events.py", line 1454, in _ensure_resolved
    return await loop.getaddrinfo(host, port, family=family, type=type,
           ^^^^^^^^^^^^^^^^^^^^^^^^^^^^^^^^^^^^^^^^^^^^^^^^^^^^^^^^^^^^
  File "/Users/minkijung/anaconda3/envs/survey_buddy/lib/python3.12/asyncio/base_events.py", line 899, in getaddrinfo
    return await self.run_in_executor(
                 ^^^^^^^^^^^^^^^^^^^^^
  File "/Users/minkijung/anaconda3/envs/survey_buddy/lib/python3.12/asyncio/base_events.py", line 861, in run_in_executor
    executor.submit(func, *args), loop=self)
    ^^^^^^^^^^^^^^^^^^^^^^^^^^^^
  File "/Users/minkijung/anaconda3/envs/survey_buddy/lib/python3.12/concurrent/futures/thread.py", line 170, in submit
    raise RuntimeError('cannot schedule new futures after shutdown')
RuntimeError: cannot schedule new futures after shutdown
unhandled exception during asyncio.run() shutdown
task: <Task finished name='Task-6' coro=<Resolver.load.<locals>.loader() done, defined at /Users/minkijung/anaconda3/envs/survey_buddy/lib/python3.12/site-packages/modal/_resolver.py:118> exception=RuntimeError('cannot schedule new futures after shutdown')>
Traceback (most recent call last):
  File "/Users/minkijung/anaconda3/envs/survey_buddy/lib/python3.12/site-packages/modal/runner.py", line 289, in _run_stub
    raise e
  File "/Users/minkijung/anaconda3/envs/survey_buddy/lib/python3.12/site-packages/modal/runner.py", line 243, in _run_stub
    await _create_all_objects(
  File "/Users/minkijung/anaconda3/envs/survey_buddy/lib/python3.12/site-packages/modal/runner.py", line 137, in _create_all_objects
    await resolver.load(obj, existing_object_id)
  File "/Users/minkijung/anaconda3/envs/survey_buddy/lib/python3.12/site-packages/modal/_resolver.py", line 149, in load
    return await cached_future
           ^^^^^^^^^^^^^^^^^^^
  File "/Users/minkijung/anaconda3/envs/survey_buddy/lib/python3.12/site-packages/modal/_resolver.py", line 121, in loader
    await asyncio.gather(*[self.load(dep) for dep in obj.deps()])
  File "/Users/minkijung/anaconda3/envs/survey_buddy/lib/python3.12/site-packages/modal/_resolver.py", line 149, in load
    return await cached_future
           ^^^^^^^^^^^^^^^^^^^
  File "/Users/minkijung/anaconda3/envs/survey_buddy/lib/python3.12/site-packages/modal/_resolver.py", line 125, in loader
    await obj._load(obj, self, existing_object_id)
  File "/Users/minkijung/anaconda3/envs/survey_buddy/lib/python3.12/site-packages/modal/image.py", line 400, in _load
    await join()
  File "/Users/minkijung/anaconda3/envs/survey_buddy/lib/python3.12/site-packages/modal/image.py", line 383, in join
    async for response in unary_stream(resolver.client.stub.ImageJoinStreaming, request):
  File "/Users/minkijung/anaconda3/envs/survey_buddy/lib/python3.12/site-packages/modal/_utils/grpc_utils.py", line 202, in unary_stream
    await stream.send_message(request, end=True)
  File "/Users/minkijung/anaconda3/envs/survey_buddy/lib/python3.12/site-packages/grpclib/client.py", line 241, in send_message
    await self.send_request()
  File "/Users/minkijung/anaconda3/envs/survey_buddy/lib/python3.12/site-packages/grpclib/client.py", line 173, in send_request
    protocol = await self._channel.__connect__()
               ^^^^^^^^^^^^^^^^^^^^^^^^^^^^^^^^^
  File "/Users/minkijung/anaconda3/envs/survey_buddy/lib/python3.12/site-packages/modal/_utils/grpc_utils.py", line 114, in __connect__
    protocol = await self._create_connection()
               ^^^^^^^^^^^^^^^^^^^^^^^^^^^^^^^
  File "/Users/minkijung/anaconda3/envs/survey_buddy/lib/python3.12/site-packages/grpclib/client.py", line 725, in _create_connection
    _, protocol = await self._loop.create_connection(
                  ^^^^^^^^^^^^^^^^^^^^^^^^^^^^^^^^^^^
  File "/Users/minkijung/anaconda3/envs/survey_buddy/lib/python3.12/asyncio/base_events.py", line 1078, in create_connection
    infos = await self._ensure_resolved(
            ^^^^^^^^^^^^^^^^^^^^^^^^^^^^
  File "/Users/minkijung/anaconda3/envs/survey_buddy/lib/python3.12/asyncio/base_events.py", line 1454, in _ensure_resolved
    return await loop.getaddrinfo(host, port, family=family, type=type,
           ^^^^^^^^^^^^^^^^^^^^^^^^^^^^^^^^^^^^^^^^^^^^^^^^^^^^^^^^^^^^
  File "/Users/minkijung/anaconda3/envs/survey_buddy/lib/python3.12/asyncio/base_events.py", line 899, in getaddrinfo
    return await self.run_in_executor(
                 ^^^^^^^^^^^^^^^^^^^^^
  File "/Users/minkijung/anaconda3/envs/survey_buddy/lib/python3.12/asyncio/base_events.py", line 861, in run_in_executor
    executor.submit(func, *args), loop=self)
    ^^^^^^^^^^^^^^^^^^^^^^^^^^^^
  File "/Users/minkijung/anaconda3/envs/survey_buddy/lib/python3.12/concurrent/futures/thread.py", line 170, in submit
    raise RuntimeError('cannot schedule new futures after shutdown')
RuntimeError: cannot schedule new futures after shutdown
1 change detected
1 change detected
1 change detected
1 change detected
